<?xml version='1.0' encoding='utf-8'?>
<robot name="">
  <joint name="base_fixed_joint" type="fixed">
    <origin xyz="0. 0. 0." rpy="0. 0. 0." />
    <parent link="body" />
    <child link="link_0" />
  </joint>
  <joint name="elbow_joint" type="revolute">
    <origin xyz="0. 0. -0.429" rpy="0. -0. -0." />
    <parent link="link_2" />
    <child link="link_3" />
    <axis xyz="1. 0. 0." />
    <limit lower="-2.7576202" upper="2.7576202" effort="30000." velocity="30.0000005" />
  </joint>
  <joint name="flange_fixed_joint" type="fixed">
    <origin xyz="-0.0000001 -0.0000617 0.0001164" rpy="0.0002284 1.5699339 -0.0002291" />
    <parent link="link_6" />
    <child link="flange_link" />
  </joint>
  <joint name="shoulder_1_joint" type="revolute">
    <origin xyz="0. 0. 0.1484" rpy="0. -1.5707964 0. " />
    <parent link="link_0" />
    <child link="link_1" />
    <axis xyz="1. 0. 0." />
    <limit lower="-6.2831853" upper="6.2831853" effort="30000." velocity="30.0000005" />
  </joint>
  <joint name="shoulder_2_joint" type="revolute">
    <origin xyz="0. 0. 0." rpy="-1.570796 -0.0000003 1.5707963" />
    <parent link="link_1" />
    <child link="link_2" />
    <axis xyz="1. 0. 0." />
    <limit lower="-6.2831853" upper="6.2831853" effort="30000." velocity="30.0000005" />
  </joint>
  <joint name="wrist_1_joint" type="revolute">
    <origin xyz="-0.1478 -0. -0.386 " rpy="1.570796 0. 0. " />
    <parent link="link_3" />
    <child link="link_4" />
    <axis xyz="1. 0. 0." />
    <limit lower="-6.2831853" upper="6.2831853" effort="30000." velocity="30.0000005" />
  </joint>
  <joint name="wrist_2_joint" type="revolute">
    <origin xyz="0. -0.1315 0. " rpy="-0. -0. -1.570796" />
    <parent link="link_4" />
    <child link="link_5" />
    <axis xyz="1. 0. 0." />
    <limit lower="-6.2831853" upper="6.2831853" effort="30000." velocity="30.0000005" />
  </joint>
  <joint name="wrist_3_joint" type="revolute">
    <origin xyz="0.0000616 -0.1349499 -0.0001164" rpy="0.0000002 0.0008624 -1.5703388" />
    <parent link="link_5" />
    <child link="link_6" />
    <axis xyz="1. 0. 0." />
    <limit lower="-6.2831853" upper="6.2831853" effort="30000." velocity="30.0000005" />
  </joint>
  <link name="body"><inertial><origin xyz="0 0 0" rpy="0 0 0" /><mass value="1e-3" /><inertia ixx="1e-6" ixy="0" ixz="0" iyy="1e-6" iyz="0" izz="1e-6" /></inertial></link>
  <link name="flange_link">
    <inertial>
      <origin xyz="0. 0. 0." rpy="0. 0. 0." />
      <mass value="0.000001" />
      <inertia ixx="0.00001" ixy="0." ixz="0." iyy="0.00001" iyz="0." izz="0.00001" />
    </inertial>
  </link>
  <link name="link_0">
    <inertial>
      <origin xyz="0. 0. 0." rpy="0. 0. 0." />
      <mass value="1." />
      <inertia ixx="0.0027098" ixy="-0.0000021" ixz="-0.0000257" iyy="0.0027497" iyz="-0.0000081" izz="0.002585" />
    </inertial>
    <visual>
      <origin xyz="0. 0. 0." rpy="0. 0. 0." />
      <geometry>
        <mesh filename="meshes/link_0_visuals.obj" scale="1. 1. 1." />
      </geometry>
    </visual>
    <collision>
      <origin xyz="0. 0. 0." rpy="0. 0. 0." />
      <geometry>
        <mesh filename="meshes/link_0_collisions.obj" scale="1. 1. 1." />
      </geometry>
    </collision>
  </link>
  <link name="link_1">
    <inertial>
      <origin xyz="0. 0. 0." rpy="0. 0. 0." />
      <mass value="4.3200002" />
      <inertia ixx="0.0145723" ixy="0.0000532" ixz="0.0000232" iyy="0.0133901" iyz="-0.0000334" izz="0.0093386" />
    </inertial>
    <visual>
      <origin xyz="0. 0. 0." rpy="0. 1.5707964 0. " />
      <geometry>
        <mesh filename="meshes/link_1_visuals.obj" scale="1. 1. 1." />
      </geometry>
    </visual>
    <collision>
      <origin xyz="0. 0. 0." rpy="0. 1.5707964 0. " />
      <geometry>
        <mesh filename="meshes/link_1_collisions.obj" scale="1. 1. 1." />
      </geometry>
    </collision>
  </link>
  <link name="link_2">
    <inertial>
      <origin xyz="0. 0. 0." rpy="0. 0. 0." />
      <mass value="9.7959995" />
      <inertia ixx="0.2549288" ixy="0.0025201" ixz="-0.3156669" iyy="0.9154209" iyz="0.0013046" izz="0.6815184" />
    </inertial>
    <visual>
      <origin xyz="0. 0. 0." rpy="0. 1.5707963 0. " />
      <geometry>
        <mesh filename="meshes/link_2_visuals.obj" scale="1. 1. 1." />
      </geometry>
    </visual>
    <collision>
      <origin xyz="0. 0. 0." rpy="0. 1.5707963 0. " />
      <geometry>
        <mesh filename="meshes/link_2_collisions.obj" scale="1. 1. 1." />
      </geometry>
    </collision>
  </link>
  <link name="link_3">
    <inertial>
      <origin xyz="0. 0. 0." rpy="0. 0. 0." />
      <mass value="2.7780001" />
      <inertia ixx="0.0070992" ixy="0.0001554" ixz="-0.014717" iyy="0.1658591" iyz="0.0000152" izz="0.1625565" />
    </inertial>
    <visual>
      <origin xyz="-0. -0. 0." rpy="0. 1.5707964 0. " />
      <geometry>
        <mesh filename="meshes/link_3_visuals.obj" scale="1. 1. 1." />
      </geometry>
    </visual>
    <collision>
      <origin xyz="-0. -0. 0." rpy="0. 1.5707964 0. " />
      <geometry>
        <mesh filename="meshes/link_3_collisions.obj" scale="1. 1. 1." />
      </geometry>
    </collision>
  </link>
  <link name="link_4">
    <inertial>
      <origin xyz="0. 0. 0." rpy="0. 0. 0." />
      <mass value="1.77" />
      <inertia ixx="0.0037578" ixy="-0.0000502" ixz="0.0000041" iyy="0.0023305" iyz="0.0000044" izz="0.0032368" />
    </inertial>
    <visual>
      <origin xyz="0. 0. 0." rpy="-0.0000001 1.5707963 0. " />
      <geometry>
        <mesh filename="meshes/link_4_visuals.obj" scale="1. 1. 1." />
      </geometry>
    </visual>
    <collision>
      <origin xyz="0. 0. 0." rpy="-0.0000001 1.5707963 0. " />
      <geometry>
        <mesh filename="meshes/link_4_collisions.obj" scale="1. 1. 1." />
      </geometry>
    </collision>
  </link>
  <link name="link_5">
    <inertial>
      <origin xyz="0. 0. 0." rpy="0. 0. 0." />
      <mass value="1.77" />
      <inertia ixx="0.0037578" ixy="0.0000502" ixz="0.0000041" iyy="0.0023305" iyz="-0.0000044" izz="0.0032368" />
    </inertial>
    <visual>
      <origin xyz="-0.0000001 0. 0. " rpy="1.5705675 1.5699339 1.5710247" />
      <geometry>
        <mesh filename="meshes/link_5_visuals.obj" scale="1. 1. 1." />
      </geometry>
    </visual>
    <collision>
      <origin xyz="-0.0000001 0. 0. " rpy="1.5705675 1.5699339 1.5710247" />
      <geometry>
        <mesh filename="meshes/link_5_collisions.obj" scale="1. 1. 1." />
      </geometry>
    </collision>
  </link>
  <link name="link_6">
    <inertial>
      <origin xyz="0. 0. 0." rpy="0. 0. 0." />
      <mass value="0.72" />
      <inertia ixx="0.0026833" ixy="-0.0002063" ixz="0.0000062" iyy="0.0011015" iyz="0.0000099" izz="0.0022617" />
    </inertial>
    <visual>
      <origin xyz="-0.0000001 -0.0000617 0.0001164" rpy="0.0002284 1.5699339 -0.0002291" />
      <geometry>
        <mesh filename="meshes/link_6_visuals.obj" scale="1. 1. 1." />
      </geometry>
    </visual>
    <collision>
      <origin xyz="-0.0000001 -0.0000617 0.0001164" rpy="0.0002284 1.5699339 -0.0002291" />
      <geometry>
        <mesh filename="meshes/link_6_collisions.obj" scale="1. 1. 1." />
      </geometry>
    </collision>
  </link>
</robot>