<?xml version="1.0" ?>
<!-- =================================================================================== -->
<!-- |    This document was autogenerated by xacro from urdf\angle_excurate_arm_ver2.xacro.temp | -->
<!-- |    EDITING THIS FILE BY HAND IS NOT RECOMMENDED                                 | -->
<!-- =================================================================================== -->
<robot xmlns:xacro="http://www.ros.org/wiki/xacro" name="angle_excurate_arm_ver2">
  <material name="silver">
    <color rgba="0.700 0.700 0.700 1.000"/>
  </material>
  <transmission name="Revolute 1_tran">
    <type>transmission_interface/SimpleTransmission</type>
    <joint name="Revolute 1">
      <hardwareInterface>hardware_interface/EffortJointInterface</hardwareInterface>
    </joint>
    <actuator name="Revolute 1_actr">
      <hardwareInterface>hardware_interface/EffortJointInterface</hardwareInterface>
      <mechanicalReduction>1</mechanicalReduction>
    </actuator>
  </transmission>
  <transmission name="Revolute 2_tran">
    <type>transmission_interface/SimpleTransmission</type>
    <joint name="Revolute 2">
      <hardwareInterface>hardware_interface/EffortJointInterface</hardwareInterface>
    </joint>
    <actuator name="Revolute 2_actr">
      <hardwareInterface>hardware_interface/EffortJointInterface</hardwareInterface>
      <mechanicalReduction>1</mechanicalReduction>
    </actuator>
  </transmission>
  <transmission name="Revolute 3_tran">
    <type>transmission_interface/SimpleTransmission</type>
    <joint name="Revolute 3">
      <hardwareInterface>hardware_interface/EffortJointInterface</hardwareInterface>
    </joint>
    <actuator name="Revolute 3_actr">
      <hardwareInterface>hardware_interface/EffortJointInterface</hardwareInterface>
      <mechanicalReduction>1</mechanicalReduction>
    </actuator>
  </transmission>
  <transmission name="Revolute 4_tran">
    <type>transmission_interface/SimpleTransmission</type>
    <joint name="Revolute 4">
      <hardwareInterface>hardware_interface/EffortJointInterface</hardwareInterface>
    </joint>
    <actuator name="Revolute 4_actr">
      <hardwareInterface>hardware_interface/EffortJointInterface</hardwareInterface>
      <mechanicalReduction>1</mechanicalReduction>
    </actuator>
  </transmission>
  <transmission name="Revolute 5_tran">
    <type>transmission_interface/SimpleTransmission</type>
    <joint name="Revolute 5">
      <hardwareInterface>hardware_interface/EffortJointInterface</hardwareInterface>
    </joint>
    <actuator name="Revolute 5_actr">
      <hardwareInterface>hardware_interface/EffortJointInterface</hardwareInterface>
      <mechanicalReduction>1</mechanicalReduction>
    </actuator>
  </transmission>
  <transmission name="Revolute 6_tran">
    <type>transmission_interface/SimpleTransmission</type>
    <joint name="Revolute 6">
      <hardwareInterface>hardware_interface/EffortJointInterface</hardwareInterface>
    </joint>
    <actuator name="Revolute 6_actr">
      <hardwareInterface>hardware_interface/EffortJointInterface</hardwareInterface>
      <mechanicalReduction>1</mechanicalReduction>
    </actuator>
  </transmission>
  <!-- omitted .gazebo include -->
  <link name="base_link">
    
    <visual>
      <origin xyz="0.0 0.0 0.0" rpy="0.0 0.0 0.0"/>
      <geometry>
        <mesh filename="angle_excurate_arm_ver2_description/meshes/base_link.stl" scale="0.001 0.001 0.001"/>
      </geometry>
      <material name="silver"/>
    </visual>
    <collision>
      <origin xyz="0.0 0.0 0.0" rpy="0.0 0.0 0.0"/>
      <geometry>
        <mesh filename="angle_excurate_arm_ver2_description/meshes/base_link.stl" scale="0.001 0.001 0.001"/>
      </geometry>
    </collision>
  </link>
  <link name="base_link2_v2_1">
    
    <visual>
      <origin xyz="0.0 -0.0 -0.076" rpy="0.0 0.0 0.0"/>
      <geometry>
        <mesh filename="angle_excurate_arm_ver2_description/meshes/base_link2_v2_1.stl" scale="0.001 0.001 0.001"/>
      </geometry>
      <material name="silver"/>
    </visual>
    <collision>
      <origin xyz="0.0 -0.0 -0.076" rpy="0.0 0.0 0.0"/>
      <geometry>
        <mesh filename="angle_excurate_arm_ver2_description/meshes/base_link2_v2_1.stl" scale="0.001 0.001 0.001"/>
      </geometry>
    </collision>
  </link>
  <link name="link3_v1_1">
    
    <visual>
      <origin xyz="0.0 0.0 -0.146342" rpy="0.0 0.0 0.0"/>
      <geometry>
        <mesh filename="angle_excurate_arm_ver2_description/meshes/link3_v1_1.stl" scale="0.001 0.001 0.001"/>
      </geometry>
      <material name="silver"/>
    </visual>
    <collision>
      <origin xyz="0.0 0.0 -0.146342" rpy="0.0 0.0 0.0"/>
      <geometry>
        <mesh filename="angle_excurate_arm_ver2_description/meshes/link3_v1_1.stl" scale="0.001 0.001 0.001"/>
      </geometry>
    </collision>
  </link>
  <link name="link4_v1_1">
    
    <visual>
      <origin xyz="-0.137776 0.0 -0.310538" rpy="0.0 0.0 0.0"/>
      <geometry>
        <mesh filename="angle_excurate_arm_ver2_description/meshes/link4_v1_1.stl" scale="0.001 0.001 0.001"/>
      </geometry>
      <material name="silver"/>
    </visual>
    <collision>
      <origin xyz="-0.137776 0.0 -0.310538" rpy="0.0 0.0 0.0"/>
      <geometry>
        <mesh filename="angle_excurate_arm_ver2_description/meshes/link4_v1_1.stl" scale="0.001 0.001 0.001"/>
      </geometry>
    </collision>
  </link>
  <link name="robot_ver7_link_4_v1_1">
    
    <visual>
      <origin xyz="-0.36806 0.0 -0.352664" rpy="0.0 0.0 0.0"/>
      <geometry>
        <mesh filename="angle_excurate_arm_ver2_description/meshes/robot_ver7_link_4_v1_1.stl" scale="0.001 0.001 0.001"/>
      </geometry>
      <material name="silver"/>
    </visual>
    <collision>
      <origin xyz="-0.36806 0.0 -0.352664" rpy="0.0 0.0 0.0"/>
      <geometry>
        <mesh filename="angle_excurate_arm_ver2_description/meshes/robot_ver7_link_4_v1_1.stl" scale="0.001 0.001 0.001"/>
      </geometry>
    </collision>
  </link>
  <link name="robot_ver7_grap2_2_v1_1">
    
    <visual>
      <origin xyz="-0.409619 0.0125 -0.359992" rpy="0.0 0.0 0.0"/>
      <geometry>
        <mesh filename="angle_excurate_arm_ver2_description/meshes/robot_ver7_grap2_2_v1_1.stl" scale="0.001 0.001 0.001"/>
      </geometry>
      <material name="silver"/>
    </visual>
    <collision>
      <origin xyz="-0.409619 0.0125 -0.359992" rpy="0.0 0.0 0.0"/>
      <geometry>
        <mesh filename="angle_excurate_arm_ver2_description/meshes/robot_ver7_grap2_2_v1_1.stl" scale="0.001 0.001 0.001"/>
      </geometry>
    </collision>
  </link>
  <link name="robot_ver7_grap1_2_v1_1">
    
    <visual>
      <origin xyz="-0.409619 -0.0125 -0.359992" rpy="0.0 0.0 0.0"/>
      <geometry>
        <mesh filename="angle_excurate_arm_ver2_description/meshes/robot_ver7_grap1_2_v1_1.stl" scale="0.001 0.001 0.001"/>
      </geometry>
      <material name="silver"/>
    </visual>
    <collision>
      <origin xyz="-0.409619 -0.0125 -0.359992" rpy="0.0 0.0 0.0"/>
      <geometry>
        <mesh filename="angle_excurate_arm_ver2_description/meshes/robot_ver7_grap1_2_v1_1.stl" scale="0.001 0.001 0.001"/>
      </geometry>
    </collision>
  </link>
  <link name="base_link_2_1">
    
    <visual>
      <origin xyz="-0.0 -0.0 -0.04" rpy="0.0 0.0 0.0"/>
      <geometry>
        <mesh filename="angle_excurate_arm_ver2_description/meshes/base_link_2_1.stl" scale="0.001 0.001 0.001"/>
      </geometry>
      <material name="silver"/>
    </visual>
    <collision>
      <origin xyz="-0.0 -0.0 -0.04" rpy="0.0 0.0 0.0"/>
      <geometry>
        <mesh filename="angle_excurate_arm_ver2_description/meshes/base_link_2_1.stl" scale="0.001 0.001 0.001"/>
      </geometry>
    </collision>
  </link>
  <link name="camera_1">
    
    <visual>
      <origin xyz="-0.37354 -0.0 -0.274937" rpy="0.0 0.0 0.0"/>
      <geometry>
        <mesh filename="angle_excurate_arm_ver2_description/meshes/camera_1.stl" scale="0.001 0.001 0.001"/>
      </geometry>
      <material name="silver"/>
    </visual>
    <collision>
      <origin xyz="-0.37354 -0.0 -0.274937" rpy="0.0 0.0 0.0"/>
      <geometry>
        <mesh filename="angle_excurate_arm_ver2_description/meshes/camera_1.stl" scale="0.001 0.001 0.001"/>
      </geometry>
    </collision>
  </link>
  <joint name="Revolute 1" type="revolute">
    <origin xyz="-0.0 0.0 0.036" rpy="0.0 0.0 0.0"/>
    <parent link="base_link_2_1"/>
    <child link="base_link2_v2_1"/>
    <axis xyz="0.0 -0.0 1.0"/>
    <limit upper="3.141593" lower="0.0" effort="100" velocity="100"/>
  </joint>
  <joint name="Revolute 2" type="revolute">
    <origin xyz="0.0 -0.0 0.070342" rpy="0.0 0.0 0.0"/>
    <parent link="base_link2_v2_1"/>
    <child link="link3_v1_1"/>
    <axis xyz="-0.0 -1.0 0.0"/>
    <limit upper="2.094395" lower="0.0" effort="100" velocity="100"/>
  </joint>
  <joint name="Revolute 3" type="revolute">
    <origin xyz="0.137776 0.0 0.164196" rpy="0.0 0.0 0.0"/>
    <parent link="link3_v1_1"/>
    <child link="link4_v1_1"/>
    <axis xyz="-0.0 -1.0 0.0"/>
    <limit upper="2.617994" lower="0.0" effort="100" velocity="100"/>
  </joint>
  <joint name="Revolute 4" type="revolute">
    <origin xyz="0.230284 0.0 0.042126" rpy="0.0 0.0 0.0"/>
    <parent link="link4_v1_1"/>
    <child link="robot_ver7_link_4_v1_1"/>
    <axis xyz="0.984808 0.0 0.173648"/>
    <limit upper="3.141593" lower="0.0" effort="100" velocity="100"/>
  </joint>
  <joint name="Revolute 5" type="revolute">
    <origin xyz="0.041559 -0.0125 0.007328" rpy="0.0 0.0 0.0"/>
    <parent link="robot_ver7_link_4_v1_1"/>
    <child link="robot_ver7_grap2_2_v1_1"/>
    <axis xyz="0.173648 -0.0 -0.984808"/>
    <limit upper="1.22173" lower="0.0" effort="100" velocity="100"/>
  </joint>
  <joint name="Revolute 6" type="revolute">
    <origin xyz="0.041559 0.0125 0.007328" rpy="0.0 0.0 0.0"/>
    <parent link="robot_ver7_link_4_v1_1"/>
    <child link="robot_ver7_grap1_2_v1_1"/>
    <axis xyz="-0.173648 0.0 0.984808"/>
    <limit upper="1.22173" lower="0.0" effort="100" velocity="100"/>
  </joint>
  <joint name="Rigid 8" type="fixed">
    <origin xyz="0.0 0.0 0.04" rpy="0.0 0.0 0.0"/>
    <parent link="base_link"/>
    <child link="base_link_2_1"/>
  </joint>
  <joint name="Rigid 11" type="fixed">
    <origin xyz="0.235764 0.0 -0.035601" rpy="0.0 0.0 0.0"/>
    <parent link="link4_v1_1"/>
    <child link="camera_1"/>
  </joint>
</robot>
